Workbook

Sheet 1. Nhập liệu
A1: MÁY TÍNH DÒNG TIỀN 10 NĂM
A2: DAPANO GROUP · Cash Flow First · Chỉ gõ vào những ô màu vàng
A4: Đơn vị tiền tệ dùng trong toàn bộ file: TRIỆU ĐỒNG. Ví dụ toà nhà 12 tỷ thì gõ 12000.
A6: A · TIỀN BỎ RA ĐỂ SỞ HỮU
A7: Giá mua toà nhà | B7: 12000 | C7: triệu đồng | D7: Số ghi trên hợp đồng công chứng
A8: Thuế, phí, công chứng | B8: 300 | C8: triệu đồng | D8: Thường 2–3% giá mua
A9: Phí môi giới | B9: 120 | C9: triệu đồng | D9: Bỏ trống nếu mua trực tiếp
A10: Chi phí cải tạo trước khi cho thuê | B10: 800 | C10: triệu đồng | D10: Điện nước, chống thấm, sơn, thang máy
A11: TỔNG VỐN ĐẦU TƯ | B11: =SUM(B7:B10) | C11: triệu đồng | D11: Đây mới là số tiền thật anh/chị bỏ vào tài sản
A13: B · CẤU TRÚC VỐN
A14: Vốn tự có | B14: 9500 | C14: triệu đồng | D14: Tiền của mình, không phải tiền vay
A15: Số tiền vay ngân hàng | B15: =MAX(0,B11-B14) | C15: triệu đồng | D15: Tự tính = tổng vốn − vốn tự có
A16: Tỷ lệ vay trên tổng vốn | B16: =IF(B11<=0,0,B15/B11) | D16: Trên 70% là vùng rủi ro cao
A17: Lãi suất năm đầu (ưu đãi) | B17: 0.085 | C17: %/năm | D17: Gõ 8,5% thì nhập 8.5%
A18: Lãi suất thả nổi các năm sau | B18: 0.115 | C18: %/năm | D18: Hỏi ngân hàng biên độ cộng thêm là bao nhiêu
A19: Kỳ hạn vay | B19: 20 | C19: năm | D19: Trả gốc đều, lãi tính trên dư nợ giảm dần
A21: C · VẬN HÀNH CHO THUÊ
A22: Giá thuê thu được mỗi tháng | B22: 75 | C22: triệu/tháng | D22: Giá đã ký được, không phải giá kỳ vọng
A23: Số tháng để trống mỗi năm | B23: 1 | C23: tháng | D23: Thực tế thường 0,5–2 tháng. Không có toà nào bằng 0 mãi
A24: Chi phí vận hành mỗi tháng | B24: 6 | C24: triệu/tháng | D24: Quản lý, sửa chữa, bảo hiểm, phí. Đừng để trống ô này
A25: Thuế cho thuê | B25: 0.1 | C25: % doanh thu | D25: Cá nhân cho thuê thường 10% doanh thu
A27: D · GIẢ ĐỊNH DÀI HẠN
A28: Tốc độ tăng giá thuê mỗi năm | B28: 0.04 | C28: %/năm | D28: Đừng lạc quan quá. 3–5% là hợp lý
A29: Tốc độ tăng chi phí vận hành mỗi năm | B29: 0.05 | C29: %/năm | D29: Chi phí luôn tăng nhanh hơn ta tưởng
A31: Nhập xong, mở sang sheet 2 để xem dòng tiền 10 năm, sheet 3 để xem ba kịch bản. Nếu chưa biết một con số nào đó, cứ để nguyên số mẫu rồi sửa sau — máy tính không vỡ. Em luôn sẵn sàng ngồi cùng anh/chị đọc lại kết quả này. · DAPANO GROUP

Sheet 2. Kết quả 10 năm
A1: KẾT QUẢ 10 NĂM
A2: Toàn bộ ô ở sheet này tự tính — không cần gõ gì
A4: TÓM TẮT — ĐỌC BA DÒNG NÀY TRƯỚC
A5: NOI năm 1 (lãi ròng trước trả nợ) | E5: =E15 | F5: triệu/năm
A6: Cap Rate trên tổng vốn (năm 1) | E6: =N15
A7: Dòng tiền ròng năm 1 | E7: =J15 | F7: triệu/năm
A8: Dòng tiền ròng bình quân tháng (năm 1) | E8: =J15/12 | F8: triệu/tháng
A9: DSCR năm 1 | E9: =K15
A10: Đèn cảnh báo DSCR | E10: =IF(I15<=0,"Không vay — không có rủi ro trả nợ",IF(E15/I15<1.2,"ĐÈN ĐỎ · DSCR dưới 1,2 — đòn bẩy quá căng",IF(E15/I15<1.5,"ĐÈN VÀNG · an toàn vừa đủ, đừng vay thêm","ĐÈN XANH · dòng tiền gánh được nợ")))
A11: Dòng tiền chuyển dương từ năm thứ | E11: =IFERROR(MATCH(TRUE,INDEX($J$15:$J$24>0,0),0),"chưa dương trong 10 năm")
A12: Dòng tiền luỹ kế 10 năm so với vốn tự có | E12: =IF('1. Nhập liệu'!$B$14<=0,"—",L24/'1. Nhập liệu'!$B$14) | F12: chưa tính phần tăng giá tài sản
A13: Tổng dòng tiền ròng 10 năm | E13: =SUM(J15:J24) | F13: triệu
A14: Năm | B14: Doanh thu thuê | C14: Chi phí vận hành | D14: Thuế cho thuê | E14: NOI | F14: Dư nợ đầu năm | G14: Trả gốc | H14: Trả lãi | I14: Tổng trả nợ | J14: Dòng tiền ròng | K14: DSCR | L14: Dòng tiền luỹ kế | M14: Cap Rate / giá mua | N14: Cap Rate / tổng vốn
A15: 1 | B15: =ROUND('1. Nhập liệu'!$B$22*MAX(0,12-'1. Nhập liệu'!$B$23)*(1+'1. Nhập liệu'!$B$28)^(A15-1),0) | C15: =ROUND('1. Nhập liệu'!$B$24*12*(1+'1. Nhập liệu'!$B$29)^(A15-1),0) | D15: =ROUND(B15*'1. Nhập liệu'!$B$25,0) | E15: =B15-C15-D15 | F15: =MAX(0,'1. Nhập liệu'!$B$15-IF('1. Nhập liệu'!$B$19<=0,0,'1. Nhập liệu'!$B$15/'1. Nhập liệu'!$B$19)*(A15-1)) | G15: =MIN(IF('1. Nhập liệu'!$B$19<=0,0,'1. Nhập liệu'!$B$15/'1. Nhập liệu'!$B$19),F15) | H15: =ROUND((F15+(F15-G15))/2*IF(A15=1,'1. Nhập liệu'!$B$17,'1. Nhập liệu'!$B$18),0) | I15: =G15+H15 | J15: =E15-I15 | K15: =IF(I15<=0,"—",ROUND(E15/I15,2)) | L15: =J15 | M15: =IF('1. Nhập liệu'!$B$7<=0,"—",E15/'1. Nhập liệu'!$B$7) | N15: =IF('1. Nhập liệu'!$B$11<=0,"—",E15/'1. Nhập liệu'!$B$11)
A16: 2 | B16: =ROUND('1. Nhập liệu'!$B$22*MAX(0,12-'1. Nhập liệu'!$B$23)*(1+'1. Nhập liệu'!$B$28)^(A16-1),0) | C16: =ROUND('1. Nhập liệu'!$B$24*12*(1+'1. Nhập liệu'!$B$29)^(A16-1),0) | D16: =ROUND(B16*'1. Nhập liệu'!$B$25,0) | E16: =B16-C16-D16 | F16: =MAX(0,'1. Nhập liệu'!$B$15-IF('1. Nhập liệu'!$B$19<=0,0,'1. Nhập liệu'!$B$15/'1. Nhập liệu'!$B$19)*(A16-1)) | G16: =MIN(IF('1. Nhập liệu'!$B$19<=0,0,'1. Nhập liệu'!$B$15/'1. Nhập liệu'!$B$19),F16) | H16: =ROUND((F16+(F16-G16))/2*IF(A16=1,'1. Nhập liệu'!$B$17,'1. Nhập liệu'!$B$18),0) | I16: =G16+H16 | J16: =E16-I16 | K16: =IF(I16<=0,"—",ROUND(E16/I16,2)) | L16: =L15+J16 | M16: =IF('1. Nhập liệu'!$B$7<=0,"—",E16/'1. Nhập liệu'!$B$7) | N16: =IF('1. Nhập liệu'!$B$11<=0,"—",E16/'1. Nhập liệu'!$B$11)
A17: 3 | B17: =ROUND('1. Nhập liệu'!$B$22*MAX(0,12-'1. Nhập liệu'!$B$23)*(1+'1. Nhập liệu'!$B$28)^(A17-1),0) | C17: =ROUND('1. Nhập liệu'!$B$24*12*(1+'1. Nhập liệu'!$B$29)^(A17-1),0) | D17: =ROUND(B17*'1. Nhập liệu'!$B$25,0) | E17: =B17-C17-D17 | F17: =MAX(0,'1. Nhập liệu'!$B$15-IF('1. Nhập liệu'!$B$19<=0,0,'1. Nhập liệu'!$B$15/'1. Nhập liệu'!$B$19)*(A17-1)) | G17: =MIN(IF('1. Nhập liệu'!$B$19<=0,0,'1. Nhập liệu'!$B$15/'1. Nhập liệu'!$B$19),F17) | H17: =ROUND((F17+(F17-G17))/2*IF(A17=1,'1. Nhập liệu'!$B$17,'1. Nhập liệu'!$B$18),0) | I17: =G17+H17 | J17: =E17-I17 | K17: =IF(I17<=0,"—",ROUND(E17/I17,2)) | L17: =L16+J17 | M17: =IF('1. Nhập liệu'!$B$7<=0,"—",E17/'1. Nhập liệu'!$B$7) | N17: =IF('1. Nhập liệu'!$B$11<=0,"—",E17/'1. Nhập liệu'!$B$11)
A18: 4 | B18: =ROUND('1. Nhập liệu'!$B$22*MAX(0,12-'1. Nhập liệu'!$B$23)*(1+'1. Nhập liệu'!$B$28)^(A18-1),0) | C18: =ROUND('1. Nhập liệu'!$B$24*12*(1+'1. Nhập liệu'!$B$29)^(A18-1),0) | D18: =ROUND(B18*'1. Nhập liệu'!$B$25,0) | E18: =B18-C18-D18 | F18: =MAX(0,'1. Nhập liệu'!$B$15-IF('1. Nhập liệu'!$B$19<=0,0,'1. Nhập liệu'!$B$15/'1. Nhập liệu'!$B$19)*(A18-1)) | G18: =MIN(IF('1. Nhập liệu'!$B$19<=0,0,'1. Nhập liệu'!$B$15/'1. Nhập liệu'!$B$19),F18) | H18: =ROUND((F18+(F18-G18))/2*IF(A18=1,'1. Nhập liệu'!$B$17,'1. Nhập liệu'!$B$18),0) | I18: =G18+H18 | J18: =E18-I18 | K18: =IF(I18<=0,"—",ROUND(E18/I18,2)) | L18: =L17+J18 | M18: =IF('1. Nhập liệu'!$B$7<=0,"—",E18/'1. Nhập liệu'!$B$7) | N18: =IF('1. Nhập liệu'!$B$11<=0,"—",E18/'1. Nhập liệu'!$B$11)
A19: 5 | B19: =ROUND('1. Nhập liệu'!$B$22*MAX(0,12-'1. Nhập liệu'!$B$23)*(1+'1. Nhập liệu'!$B$28)^(A19-1),0) | C19: =ROUND('1. Nhập liệu'!$B$24*12*(1+'1. Nhập liệu'!$B$29)^(A19-1),0) | D19: =ROUND(B19*'1. Nhập liệu'!$B$25,0) | E19: =B19-C19-D19 | F19: =MAX(0,'1. Nhập liệu'!$B$15-IF('1. Nhập liệu'!$B$19<=0,0,'1. Nhập liệu'!$B$15/'1. Nhập liệu'!$B$19)*(A19-1)) | G19: =MIN(IF('1. Nhập liệu'!$B$19<=0,0,'1. Nhập liệu'!$B$15/'1. Nhập liệu'!$B$19),F19) | H19: =ROUND((F19+(F19-G19))/2*IF(A19=1,'1. Nhập liệu'!$B$17,'1. Nhập liệu'!$B$18),0) | I19: =G19+H19 | J19: =E19-I19 | K19: =IF(I19<=0,"—",ROUND(E19/I19,2)) | L19: =L18+J19 | M19: =IF('1. Nhập liệu'!$B$7<=0,"—",E19/'1. Nhập liệu'!$B$7) | N19: =IF('1. Nhập liệu'!$B$11<=0,"—",E19/'1. Nhập liệu'!$B$11)
A20: 6 | B20: =ROUND('1. Nhập liệu'!$B$22*MAX(0,12-'1. Nhập liệu'!$B$23)*(1+'1. Nhập liệu'!$B$28)^(A20-1),0) | C20: =ROUND('1. Nhập liệu'!$B$24*12*(1+'1. Nhập liệu'!$B$29)^(A20-1),0) | D20: =ROUND(B20*'1. Nhập liệu'!$B$25,0) | E20: =B20-C20-D20 | F20: =MAX(0,'1. Nhập liệu'!$B$15-IF('1. Nhập liệu'!$B$19<=0,0,'1. Nhập liệu'!$B$15/'1. Nhập liệu'!$B$19)*(A20-1)) | G20: =MIN(IF('1. Nhập liệu'!$B$19<=0,0,'1. Nhập liệu'!$B$15/'1. Nhập liệu'!$B$19),F20) | H20: =ROUND((F20+(F20-G20))/2*IF(A20=1,'1. Nhập liệu'!$B$17,'1. Nhập liệu'!$B$18),0) | I20: =G20+H20 | J20: =E20-I20 | K20: =IF(I20<=0,"—",ROUND(E20/I20,2)) | L20: =L19+J20 | M20: =IF('1. Nhập liệu'!$B$7<=0,"—",E20/'1. Nhập liệu'!$B$7) | N20: =IF('1. Nhập liệu'!$B$11<=0,"—",E20/'1. Nhập liệu'!$B$11)
A21: 7 | B21: =ROUND('1. Nhập liệu'!$B$22*MAX(0,12-'1. Nhập liệu'!$B$23)*(1+'1. Nhập liệu'!$B$28)^(A21-1),0) | C21: =ROUND('1. Nhập liệu'!$B$24*12*(1+'1. Nhập liệu'!$B$29)^(A21-1),0) | D21: =ROUND(B21*'1. Nhập liệu'!$B$25,0) | E21: =B21-C21-D21 | F21: =MAX(0,'1. Nhập liệu'!$B$15-IF('1. Nhập liệu'!$B$19<=0,0,'1. Nhập liệu'!$B$15/'1. Nhập liệu'!$B$19)*(A21-1)) | G21: =MIN(IF('1. Nhập liệu'!$B$19<=0,0,'1. Nhập liệu'!$B$15/'1. Nhập liệu'!$B$19),F21) | H21: =ROUND((F21+(F21-G21))/2*IF(A21=1,'1. Nhập liệu'!$B$17,'1. Nhập liệu'!$B$18),0) | I21: =G21+H21 | J21: =E21-I21 | K21: =IF(I21<=0,"—",ROUND(E21/I21,2)) | L21: =L20+J21 | M21: =IF('1. Nhập liệu'!$B$7<=0,"—",E21/'1. Nhập liệu'!$B$7) | N21: =IF('1. Nhập liệu'!$B$11<=0,"—",E21/'1. Nhập liệu'!$B$11)
A22: 8 | B22: =ROUND('1. Nhập liệu'!$B$22*MAX(0,12-'1. Nhập liệu'!$B$23)*(1+'1. Nhập liệu'!$B$28)^(A22-1),0) | C22: =ROUND('1. Nhập liệu'!$B$24*12*(1+'1. Nhập liệu'!$B$29)^(A22-1),0) | D22: =ROUND(B22*'1. Nhập liệu'!$B$25,0) | E22: =B22-C22-D22 | F22: =MAX(0,'1. Nhập liệu'!$B$15-IF('1. Nhập liệu'!$B$19<=0,0,'1. Nhập liệu'!$B$15/'1. Nhập liệu'!$B$19)*(A22-1)) | G22: =MIN(IF('1. Nhập liệu'!$B$19<=0,0,'1. Nhập liệu'!$B$15/'1. Nhập liệu'!$B$19),F22) | H22: =ROUND((F22+(F22-G22))/2*IF(A22=1,'1. Nhập liệu'!$B$17,'1. Nhập liệu'!$B$18),0) | I22: =G22+H22 | J22: =E22-I22 | K22: =IF(I22<=0,"—",ROUND(E22/I22,2)) | L22: =L21+J22 | M22: =IF('1. Nhập liệu'!$B$7<=0,"—",E22/'1. Nhập liệu'!$B$7) | N22: =IF('1. Nhập liệu'!$B$11<=0,"—",E22/'1. Nhập liệu'!$B$11)
A23: 9 | B23: =ROUND('1. Nhập liệu'!$B$22*MAX(0,12-'1. Nhập liệu'!$B$23)*(1+'1. Nhập liệu'!$B$28)^(A23-1),0) | C23: =ROUND('1. Nhập liệu'!$B$24*12*(1+'1. Nhập liệu'!$B$29)^(A23-1),0) | D23: =ROUND(B23*'1. Nhập liệu'!$B$25,0) | E23: =B23-C23-D23 | F23: =MAX(0,'1. Nhập liệu'!$B$15-IF('1. Nhập liệu'!$B$19<=0,0,'1. Nhập liệu'!$B$15/'1. Nhập liệu'!$B$19)*(A23-1)) | G23: =MIN(IF('1. Nhập liệu'!$B$19<=0,0,'1. Nhập liệu'!$B$15/'1. Nhập liệu'!$B$19),F23) | H23: =ROUND((F23+(F23-G23))/2*IF(A23=1,'1. Nhập liệu'!$B$17,'1. Nhập liệu'!$B$18),0) | I23: =G23+H23 | J23: =E23-I23 | K23: =IF(I23<=0,"—",ROUND(E23/I23,2)) | L23: =L22+J23 | M23: =IF('1. Nhập liệu'!$B$7<=0,"—",E23/'1. Nhập liệu'!$B$7) | N23: =IF('1. Nhập liệu'!$B$11<=0,"—",E23/'1. Nhập liệu'!$B$11)
A24: 10 | B24: =ROUND('1. Nhập liệu'!$B$22*MAX(0,12-'1. Nhập liệu'!$B$23)*(1+'1. Nhập liệu'!$B$28)^(A24-1),0) | C24: =ROUND('1. Nhập liệu'!$B$24*12*(1+'1. Nhập liệu'!$B$29)^(A24-1),0) | D24: =ROUND(B24*'1. Nhập liệu'!$B$25,0) | E24: =B24-C24-D24 | F24: =MAX(0,'1. Nhập liệu'!$B$15-IF('1. Nhập liệu'!$B$19<=0,0,'1. Nhập liệu'!$B$15/'1. Nhập liệu'!$B$19)*(A24-1)) | G24: =MIN(IF('1. Nhập liệu'!$B$19<=0,0,'1. Nhập liệu'!$B$15/'1. Nhập liệu'!$B$19),F24) | H24: =ROUND((F24+(F24-G24))/2*IF(A24=1,'1. Nhập liệu'!$B$17,'1. Nhập liệu'!$B$18),0) | I24: =G24+H24 | J24: =E24-I24 | K24: =IF(I24<=0,"—",ROUND(E24/I24,2)) | L24: =L23+J24 | M24: =IF('1. Nhập liệu'!$B$7<=0,"—",E24/'1. Nhập liệu'!$B$7) | N24: =IF('1. Nhập liệu'!$B$11<=0,"—",E24/'1. Nhập liệu'!$B$11)
A25: TỔNG | B25: =SUM(B15:B24) | C25: =SUM(C15:C24) | D25: =SUM(D15:D24) | E25: =SUM(E15:E24) | G25: =SUM(G15:G24) | H25: =SUM(H15:H24) | I25: =SUM(I15:I24) | J25: =SUM(J15:J24)
A27: Cách tính trả nợ: gốc đều mỗi năm, lãi tính trên dư nợ bình quân trong năm — đúng cách các ngân hàng Việt Nam đang áp dụng cho vay mua bất động sản. Năm 1 dùng lãi suất ưu đãi, từ năm 2 dùng lãi suất thả nổi. · DAPANO GROUP · Think Kind!

Sheet 3. Ba kịch bản
A1: BA KỊCH BẢN
A2: Cùng một toà nhà, ba cách đời có thể diễn ra. Ô vàng sửa được.
A4: GIẢ ĐỊNH LỆCH NHAU Ở ĐÂU
A5: Điều chỉnh so với sheet Nhập liệu | B5: THẬN TRỌNG | C5: CƠ SỞ | D5: KỲ VỌNG
A6: Giá thuê lệch | B6: -0.1 | C6: 0 | D6: 0.07
A7: Số tháng trống mỗi năm | B7: ='1. Nhập liệu'!$B$23+1.5 | C7: ='1. Nhập liệu'!$B$23 | D7: =MAX(0,'1. Nhập liệu'!$B$23-0.5)
A8: Lãi suất cộng thêm | B8: 0.02 | C8: 0 | D8: -0.005
A9: Tăng giá thuê mỗi năm | B9: =MAX(0,'1. Nhập liệu'!$B$28-0.01) | C9: ='1. Nhập liệu'!$B$28 | D9: ='1. Nhập liệu'!$B$28+0.01
A12: KỊCH BẢN 1 · THẬN TRỌNG — thuê thấp, trống nhiều, lãi suất tăng
A13: Năm | B13: Doanh thu thuê | C13: Chi phí vận hành | D13: Thuế cho thuê | E13: NOI | F13: Dư nợ đầu năm | G13: Trả gốc | H13: Trả lãi | I13: Tổng trả nợ | J13: Dòng tiền ròng | K13: DSCR
A14: 1 | B14: =ROUND('1. Nhập liệu'!$B$22*(1+$B$6)*MAX(0,12-$B$7)*(1+$B$9)^(A14-1),0) | C14: =ROUND('1. Nhập liệu'!$B$24*12*(1+'1. Nhập liệu'!$B$29)^(A14-1),0) | D14: =ROUND(B14*'1. Nhập liệu'!$B$25,0) | E14: =B14-C14-D14 | F14: =MAX(0,'1. Nhập liệu'!$B$15-IF('1. Nhập liệu'!$B$19<=0,0,'1. Nhập liệu'!$B$15/'1. Nhập liệu'!$B$19)*(A14-1)) | G14: =MIN(IF('1. Nhập liệu'!$B$19<=0,0,'1. Nhập liệu'!$B$15/'1. Nhập liệu'!$B$19),F14) | H14: =ROUND((F14+(F14-G14))/2*(IF(A14=1,'1. Nhập liệu'!$B$17,'1. Nhập liệu'!$B$18)+$B$8),0) | I14: =G14+H14 | J14: =E14-I14 | K14: =IF(I14<=0,"—",ROUND(E14/I14,2))
A15: 2 | B15: =ROUND('1. Nhập liệu'!$B$22*(1+$B$6)*MAX(0,12-$B$7)*(1+$B$9)^(A15-1),0) | C15: =ROUND('1. Nhập liệu'!$B$24*12*(1+'1. Nhập liệu'!$B$29)^(A15-1),0) | D15: =ROUND(B15*'1. Nhập liệu'!$B$25,0) | E15: =B15-C15-D15 | F15: =MAX(0,'1. Nhập liệu'!$B$15-IF('1. Nhập liệu'!$B$19<=0,0,'1. Nhập liệu'!$B$15/'1. Nhập liệu'!$B$19)*(A15-1)) | G15: =MIN(IF('1. Nhập liệu'!$B$19<=0,0,'1. Nhập liệu'!$B$15/'1. Nhập liệu'!$B$19),F15) | H15: =ROUND((F15+(F15-G15))/2*(IF(A15=1,'1. Nhập liệu'!$B$17,'1. Nhập liệu'!$B$18)+$B$8),0) | I15: =G15+H15 | J15: =E15-I15 | K15: =IF(I15<=0,"—",ROUND(E15/I15,2))
A16: 3 | B16: =ROUND('1. Nhập liệu'!$B$22*(1+$B$6)*MAX(0,12-$B$7)*(1+$B$9)^(A16-1),0) | C16: =ROUND('1. Nhập liệu'!$B$24*12*(1+'1. Nhập liệu'!$B$29)^(A16-1),0) | D16: =ROUND(B16*'1. Nhập liệu'!$B$25,0) | E16: =B16-C16-D16 | F16: =MAX(0,'1. Nhập liệu'!$B$15-IF('1. Nhập liệu'!$B$19<=0,0,'1. Nhập liệu'!$B$15/'1. Nhập liệu'!$B$19)*(A16-1)) | G16: =MIN(IF('1. Nhập liệu'!$B$19<=0,0,'1. Nhập liệu'!$B$15/'1. Nhập liệu'!$B$19),F16) | H16: =ROUND((F16+(F16-G16))/2*(IF(A16=1,'1. Nhập liệu'!$B$17,'1. Nhập liệu'!$B$18)+$B$8),0) | I16: =G16+H16 | J16: =E16-I16 | K16: =IF(I16<=0,"—",ROUND(E16/I16,2))
A17: 4 | B17: =ROUND('1. Nhập liệu'!$B$22*(1+$B$6)*MAX(0,12-$B$7)*(1+$B$9)^(A17-1),0) | C17: =ROUND('1. Nhập liệu'!$B$24*12*(1+'1. Nhập liệu'!$B$29)^(A17-1),0) | D17: =ROUND(B17*'1. Nhập liệu'!$B$25,0) | E17: =B17-C17-D17 | F17: =MAX(0,'1. Nhập liệu'!$B$15-IF('1. Nhập liệu'!$B$19<=0,0,'1. Nhập liệu'!$B$15/'1. Nhập liệu'!$B$19)*(A17-1)) | G17: =MIN(IF('1. Nhập liệu'!$B$19<=0,0,'1. Nhập liệu'!$B$15/'1. Nhập liệu'!$B$19),F17) | H17: =ROUND((F17+(F17-G17))/2*(IF(A17=1,'1. Nhập liệu'!$B$17,'1. Nhập liệu'!$B$18)+$B$8),0) | I17: =G17+H17 | J17: =E17-I17 | K17: =IF(I17<=0,"—",ROUND(E17/I17,2))
A18: 5 | B18: =ROUND('1. Nhập liệu'!$B$22*(1+$B$6)*MAX(0,12-$B$7)*(1+$B$9)^(A18-1),0) | C18: =ROUND('1. Nhập liệu'!$B$24*12*(1+'1. Nhập liệu'!$B$29)^(A18-1),0) | D18: =ROUND(B18*'1. Nhập liệu'!$B$25,0) | E18: =B18-C18-D18 | F18: =MAX(0,'1. Nhập liệu'!$B$15-IF('1. Nhập liệu'!$B$19<=0,0,'1. Nhập liệu'!$B$15/'1. Nhập liệu'!$B$19)*(A18-1)) | G18: =MIN(IF('1. Nhập liệu'!$B$19<=0,0,'1. Nhập liệu'!$B$15/'1. Nhập liệu'!$B$19),F18) | H18: =ROUND((F18+(F18-G18))/2*(IF(A18=1,'1. Nhập liệu'!$B$17,'1. Nhập liệu'!$B$18)+$B$8),0) | I18: =G18+H18 | J18: =E18-I18 | K18: =IF(I18<=0,"—",ROUND(E18/I18,2))
A19: 6 | B19: =ROUND('1. Nhập liệu'!$B$22*(1+$B$6)*MAX(0,12-$B$7)*(1+$B$9)^(A19-1),0) | C19: =ROUND('1. Nhập liệu'!$B$24*12*(1+'1. Nhập liệu'!$B$29)^(A19-1),0) | D19: =ROUND(B19*'1. Nhập liệu'!$B$25,0) | E19: =B19-C19-D19 | F19: =MAX(0,'1. Nhập liệu'!$B$15-IF('1. Nhập liệu'!$B$19<=0,0,'1. Nhập liệu'!$B$15/'1. Nhập liệu'!$B$19)*(A19-1)) | G19: =MIN(IF('1. Nhập liệu'!$B$19<=0,0,'1. Nhập liệu'!$B$15/'1. Nhập liệu'!$B$19),F19) | H19: =ROUND((F19+(F19-G19))/2*(IF(A19=1,'1. Nhập liệu'!$B$17,'1. Nhập liệu'!$B$18)+$B$8),0) | I19: =G19+H19 | J19: =E19-I19 | K19: =IF(I19<=0,"—",ROUND(E19/I19,2))
A20: 7 | B20: =ROUND('1. Nhập liệu'!$B$22*(1+$B$6)*MAX(0,12-$B$7)*(1+$B$9)^(A20-1),0) | C20: =ROUND('1. Nhập liệu'!$B$24*12*(1+'1. Nhập liệu'!$B$29)^(A20-1),0) | D20: =ROUND(B20*'1. Nhập liệu'!$B$25,0) | E20: =B20-C20-D20 | F20: =MAX(0,'1. Nhập liệu'!$B$15-IF('1. Nhập liệu'!$B$19<=0,0,'1. Nhập liệu'!$B$15/'1. Nhập liệu'!$B$19)*(A20-1)) | G20: =MIN(IF('1. Nhập liệu'!$B$19<=0,0,'1. Nhập liệu'!$B$15/'1. Nhập liệu'!$B$19),F20) | H20: =ROUND((F20+(F20-G20))/2*(IF(A20=1,'1. Nhập liệu'!$B$17,'1. Nhập liệu'!$B$18)+$B$8),0) | I20: =G20+H20 | J20: =E20-I20 | K20: =IF(I20<=0,"—",ROUND(E20/I20,2))
A21: 8 | B21: =ROUND('1. Nhập liệu'!$B$22*(1+$B$6)*MAX(0,12-$B$7)*(1+$B$9)^(A21-1),0) | C21: =ROUND('1. Nhập liệu'!$B$24*12*(1+'1. Nhập liệu'!$B$29)^(A21-1),0) | D21: =ROUND(B21*'1. Nhập liệu'!$B$25,0) | E21: =B21-C21-D21 | F21: =MAX(0,'1. Nhập liệu'!$B$15-IF('1. Nhập liệu'!$B$19<=0,0,'1. Nhập liệu'!$B$15/'1. Nhập liệu'!$B$19)*(A21-1)) | G21: =MIN(IF('1. Nhập liệu'!$B$19<=0,0,'1. Nhập liệu'!$B$15/'1. Nhập liệu'!$B$19),F21) | H21: =ROUND((F21+(F21-G21))/2*(IF(A21=1,'1. Nhập liệu'!$B$17,'1. Nhập liệu'!$B$18)+$B$8),0) | I21: =G21+H21 | J21: =E21-I21 | K21: =IF(I21<=0,"—",ROUND(E21/I21,2))
A22: 9 | B22: =ROUND('1. Nhập liệu'!$B$22*(1+$B$6)*MAX(0,12-$B$7)*(1+$B$9)^(A22-1),0) | C22: =ROUND('1. Nhập liệu'!$B$24*12*(1+'1. Nhập liệu'!$B$29)^(A22-1),0) | D22: =ROUND(B22*'1. Nhập liệu'!$B$25,0) | E22: =B22-C22-D22 | F22: =MAX(0,'1. Nhập liệu'!$B$15-IF('1. Nhập liệu'!$B$19<=0,0,'1. Nhập liệu'!$B$15/'1. Nhập liệu'!$B$19)*(A22-1)) | G22: =MIN(IF('1. Nhập liệu'!$B$19<=0,0,'1. Nhập liệu'!$B$15/'1. Nhập liệu'!$B$19),F22) | H22: =ROUND((F22+(F22-G22))/2*(IF(A22=1,'1. Nhập liệu'!$B$17,'1. Nhập liệu'!$B$18)+$B$8),0) | I22: =G22+H22 | J22: =E22-I22 | K22: =IF(I22<=0,"—",ROUND(E22/I22,2))
A23: 10 | B23: =ROUND('1. Nhập liệu'!$B$22*(1+$B$6)*MAX(0,12-$B$7)*(1+$B$9)^(A23-1),0) | C23: =ROUND('1. Nhập liệu'!$B$24*12*(1+'1. Nhập liệu'!$B$29)^(A23-1),0) | D23: =ROUND(B23*'1. Nhập liệu'!$B$25,0) | E23: =B23-C23-D23 | F23: =MAX(0,'1. Nhập liệu'!$B$15-IF('1. Nhập liệu'!$B$19<=0,0,'1. Nhập liệu'!$B$15/'1. Nhập liệu'!$B$19)*(A23-1)) | G23: =MIN(IF('1. Nhập liệu'!$B$19<=0,0,'1. Nhập liệu'!$B$15/'1. Nhập liệu'!$B$19),F23) | H23: =ROUND((F23+(F23-G23))/2*(IF(A23=1,'1. Nhập liệu'!$B$17,'1. Nhập liệu'!$B$18)+$B$8),0) | I23: =G23+H23 | J23: =E23-I23 | K23: =IF(I23<=0,"—",ROUND(E23/I23,2))
A24: TỔNG | B24: =SUM(B14:B23) | C24: =SUM(C14:C23) | D24: =SUM(D14:D23) | E24: =SUM(E14:E23) | G24: =SUM(G14:G23) | H24: =SUM(H14:H23) | I24: =SUM(I14:I23) | J24: =SUM(J14:J23)
A26: KỊCH BẢN 2 · CƠ SỞ — đúng như số đã nhập
A27: Năm | B27: Doanh thu thuê | C27: Chi phí vận hành | D27: Thuế cho thuê | E27: NOI | F27: Dư nợ đầu năm | G27: Trả gốc | H27: Trả lãi | I27: Tổng trả nợ | J27: Dòng tiền ròng | K27: DSCR
A28: 1 | B28: =ROUND('1. Nhập liệu'!$B$22*(1+$C$6)*MAX(0,12-$C$7)*(1+$C$9)^(A28-1),0) | C28: =ROUND('1. Nhập liệu'!$B$24*12*(1+'1. Nhập liệu'!$B$29)^(A28-1),0) | D28: =ROUND(B28*'1. Nhập liệu'!$B$25,0) | E28: =B28-C28-D28 | F28: =MAX(0,'1. Nhập liệu'!$B$15-IF('1. Nhập liệu'!$B$19<=0,0,'1. Nhập liệu'!$B$15/'1. Nhập liệu'!$B$19)*(A28-1)) | G28: =MIN(IF('1. Nhập liệu'!$B$19<=0,0,'1. Nhập liệu'!$B$15/'1. Nhập liệu'!$B$19),F28) | H28: =ROUND((F28+(F28-G28))/2*(IF(A28=1,'1. Nhập liệu'!$B$17,'1. Nhập liệu'!$B$18)+$C$8),0) | I28: =G28+H28 | J28: =E28-I28 | K28: =IF(I28<=0,"—",ROUND(E28/I28,2))
A29: 2 | B29: =ROUND('1. Nhập liệu'!$B$22*(1+$C$6)*MAX(0,12-$C$7)*(1+$C$9)^(A29-1),0) | C29: =ROUND('1. Nhập liệu'!$B$24*12*(1+'1. Nhập liệu'!$B$29)^(A29-1),0) | D29: =ROUND(B29*'1. Nhập liệu'!$B$25,0) | E29: =B29-C29-D29 | F29: =MAX(0,'1. Nhập liệu'!$B$15-IF('1. Nhập liệu'!$B$19<=0,0,'1. Nhập liệu'!$B$15/'1. Nhập liệu'!$B$19)*(A29-1)) | G29: =MIN(IF('1. Nhập liệu'!$B$19<=0,0,'1. Nhập liệu'!$B$15/'1. Nhập liệu'!$B$19),F29) | H29: =ROUND((F29+(F29-G29))/2*(IF(A29=1,'1. Nhập liệu'!$B$17,'1. Nhập liệu'!$B$18)+$C$8),0) | I29: =G29+H29 | J29: =E29-I29 | K29: =IF(I29<=0,"—",ROUND(E29/I29,2))
A30: 3 | B30: =ROUND('1. Nhập liệu'!$B$22*(1+$C$6)*MAX(0,12-$C$7)*(1+$C$9)^(A30-1),0) | C30: =ROUND('1. Nhập liệu'!$B$24*12*(1+'1. Nhập liệu'!$B$29)^(A30-1),0) | D30: =ROUND(B30*'1. Nhập liệu'!$B$25,0) | E30: =B30-C30-D30 | F30: =MAX(0,'1. Nhập liệu'!$B$15-IF('1. Nhập liệu'!$B$19<=0,0,'1. Nhập liệu'!$B$15/'1. Nhập liệu'!$B$19)*(A30-1)) | G30: =MIN(IF('1. Nhập liệu'!$B$19<=0,0,'1. Nhập liệu'!$B$15/'1. Nhập liệu'!$B$19),F30) | H30: =ROUND((F30+(F30-G30))/2*(IF(A30=1,'1. Nhập liệu'!$B$17,'1. Nhập liệu'!$B$18)+$C$8),0) | I30: =G30+H30 | J30: =E30-I30 | K30: =IF(I30<=0,"—",ROUND(E30/I30,2))
A31: 4 | B31: =ROUND('1. Nhập liệu'!$B$22*(1+$C$6)*MAX(0,12-$C$7)*(1+$C$9)^(A31-1),0) | C31: =ROUND('1. Nhập liệu'!$B$24*12*(1+'1. Nhập liệu'!$B$29)^(A31-1),0) | D31: =ROUND(B31*'1. Nhập liệu'!$B$25,0) | E31: =B31-C31-D31 | F31: =MAX(0,'1. Nhập liệu'!$B$15-IF('1. Nhập liệu'!$B$19<=0,0,'1. Nhập liệu'!$B$15/'1. Nhập liệu'!$B$19)*(A31-1)) | G31: =MIN(IF('1. Nhập liệu'!$B$19<=0,0,'1. Nhập liệu'!$B$15/'1. Nhập liệu'!$B$19),F31) | H31: =ROUND((F31+(F31-G31))/2*(IF(A31=1,'1. Nhập liệu'!$B$17,'1. Nhập liệu'!$B$18)+$C$8),0) | I31: =G31+H31 | J31: =E31-I31 | K31: =IF(I31<=0,"—",ROUND(E31/I31,2))
A32: 5 | B32: =ROUND('1. Nhập liệu'!$B$22*(1+$C$6)*MAX(0,12-$C$7)*(1+$C$9)^(A32-1),0) | C32: =ROUND('1. Nhập liệu'!$B$24*12*(1+'1. Nhập liệu'!$B$29)^(A32-1),0) | D32: =ROUND(B32*'1. Nhập liệu'!$B$25,0) | E32: =B32-C32-D32 | F32: =MAX(0,'1. Nhập liệu'!$B$15-IF('1. Nhập liệu'!$B$19<=0,0,'1. Nhập liệu'!$B$15/'1. Nhập liệu'!$B$19)*(A32-1)) | G32: =MIN(IF('1. Nhập liệu'!$B$19<=0,0,'1. Nhập liệu'!$B$15/'1. Nhập liệu'!$B$19),F32) | H32: =ROUND((F32+(F32-G32))/2*(IF(A32=1,'1. Nhập liệu'!$B$17,'1. Nhập liệu'!$B$18)+$C$8),0) | I32: =G32+H32 | J32: =E32-I32 | K32: =IF(I32<=0,"—",ROUND(E32/I32,2))
A33: 6 | B33: =ROUND('1. Nhập liệu'!$B$22*(1+$C$6)*MAX(0,12-$C$7)*(1+$C$9)^(A33-1),0) | C33: =ROUND('1. Nhập liệu'!$B$24*12*(1+'1. Nhập liệu'!$B$29)^(A33-1),0) | D33: =ROUND(B33*'1. Nhập liệu'!$B$25,0) | E33: =B33-C33-D33 | F33: =MAX(0,'1. Nhập liệu'!$B$15-IF('1. Nhập liệu'!$B$19<=0,0,'1. Nhập liệu'!$B$15/'1. Nhập liệu'!$B$19)*(A33-1)) | G33: =MIN(IF('1. Nhập liệu'!$B$19<=0,0,'1. Nhập liệu'!$B$15/'1. Nhập liệu'!$B$19),F33) | H33: =ROUND((F33+(F33-G33))/2*(IF(A33=1,'1. Nhập liệu'!$B$17,'1. Nhập liệu'!$B$18)+$C$8),0) | I33: =G33+H33 | J33: =E33-I33 | K33: =IF(I33<=0,"—",ROUND(E33/I33,2))
A34: 7 | B34: =ROUND('1. Nhập liệu'!$B$22*(1+$C$6)*MAX(0,12-$C$7)*(1+$C$9)^(A34-1),0) | C34: =ROUND('1. Nhập liệu'!$B$24*12*(1+'1. Nhập liệu'!$B$29)^(A34-1),0) | D34: =ROUND(B34*'1. Nhập liệu'!$B$25,0) | E34: =B34-C34-D34 | F34: =MAX(0,'1. Nhập liệu'!$B$15-IF('1. Nhập liệu'!$B$19<=0,0,'1. Nhập liệu'!$B$15/'1. Nhập liệu'!$B$19)*(A34-1)) | G34: =MIN(IF('1. Nhập liệu'!$B$19<=0,0,'1. Nhập liệu'!$B$15/'1. Nhập liệu'!$B$19),F34) | H34: =ROUND((F34+(F34-G34))/2*(IF(A34=1,'1. Nhập liệu'!$B$17,'1. Nhập liệu'!$B$18)+$C$8),0) | I34: =G34+H34 | J34: =E34-I34 | K34: =IF(I34<=0,"—",ROUND(E34/I34,2))
A35: 8 | B35: =ROUND('1. Nhập liệu'!$B$22*(1+$C$6)*MAX(0,12-$C$7)*(1+$C$9)^(A35-1),0) | C35: =ROUND('1. Nhập liệu'!$B$24*12*(1+'1. Nhập liệu'!$B$29)^(A35-1),0) | D35: =ROUND(B35*'1. Nhập liệu'!$B$25,0) | E35: =B35-C35-D35 | F35: =MAX(0,'1. Nhập liệu'!$B$15-IF('1. Nhập liệu'!$B$19<=0,0,'1. Nhập liệu'!$B$15/'1. Nhập liệu'!$B$19)*(A35-1)) | G35: =MIN(IF('1. Nhập liệu'!$B$19<=0,0,'1. Nhập liệu'!$B$15/'1. Nhập liệu'!$B$19),F35) | H35: =ROUND((F35+(F35-G35))/2*(IF(A35=1,'1. Nhập liệu'!$B$17,'1. Nhập liệu'!$B$18)+$C$8),0) | I35: =G35+H35 | J35: =E35-I35 | K35: =IF(I35<=0,"—",ROUND(E35/I35,2))
A36: 9 | B36: =ROUND('1. Nhập liệu'!$B$22*(1+$C$6)*MAX(0,12-$C$7)*(1+$C$9)^(A36-1),0) | C36: =ROUND('1. Nhập liệu'!$B$24*12*(1+'1. Nhập liệu'!$B$29)^(A36-1),0) | D36: =ROUND(B36*'1. Nhập liệu'!$B$25,0) | E36: =B36-C36-D36 | F36: =MAX(0,'1. Nhập liệu'!$B$15-IF('1. Nhập liệu'!$B$19<=0,0,'1. Nhập liệu'!$B$15/'1. Nhập liệu'!$B$19)*(A36-1)) | G36: =MIN(IF('1. Nhập liệu'!$B$19<=0,0,'1. Nhập liệu'!$B$15/'1. Nhập liệu'!$B$19),F36) | H36: =ROUND((F36+(F36-G36))/2*(IF(A36=1,'1. Nhập liệu'!$B$17,'1. Nhập liệu'!$B$18)+$C$8),0) | I36: =G36+H36 | J36: =E36-I36 | K36: =IF(I36<=0,"—",ROUND(E36/I36,2))
A37: 10 | B37: =ROUND('1. Nhập liệu'!$B$22*(1+$C$6)*MAX(0,12-$C$7)*(1+$C$9)^(A37-1),0) | C37: =ROUND('1. Nhập liệu'!$B$24*12*(1+'1. Nhập liệu'!$B$29)^(A37-1),0) | D37: =ROUND(B37*'1. Nhập liệu'!$B$25,0) | E37: =B37-C37-D37 | F37: =MAX(0,'1. Nhập liệu'!$B$15-IF('1. Nhập liệu'!$B$19<=0,0,'1. Nhập liệu'!$B$15/'1. Nhập liệu'!$B$19)*(A37-1)) | G37: =MIN(IF('1. Nhập liệu'!$B$19<=0,0,'1. Nhập liệu'!$B$15/'1. Nhập liệu'!$B$19),F37) | H37: =ROUND((F37+(F37-G37))/2*(IF(A37=1,'1. Nhập liệu'!$B$17,'1. Nhập liệu'!$B$18)+$C$8),0) | I37: =G37+H37 | J37: =E37-I37 | K37: =IF(I37<=0,"—",ROUND(E37/I37,2))
A38: TỔNG | B38: =SUM(B28:B37) | C38: =SUM(C28:C37) | D38: =SUM(D28:D37) | E38: =SUM(E28:E37) | G38: =SUM(G28:G37) | H38: =SUM(H28:H37) | I38: =SUM(I28:I37) | J38: =SUM(J28:J37)
A40: KỊCH BẢN 3 · KỲ VỌNG — thuê tốt, ít trống, lãi suất dễ thở
A41: Năm | B41: Doanh thu thuê | C41: Chi phí vận hành | D41: Thuế cho thuê | E41: NOI | F41: Dư nợ đầu năm | G41: Trả gốc | H41: Trả lãi | I41: Tổng trả nợ | J41: Dòng tiền ròng | K41: DSCR
A42: 1 | B42: =ROUND('1. Nhập liệu'!$B$22*(1+$D$6)*MAX(0,12-$D$7)*(1+$D$9)^(A42-1),0) | C42: =ROUND('1. Nhập liệu'!$B$24*12*(1+'1. Nhập liệu'!$B$29)^(A42-1),0) | D42: =ROUND(B42*'1. Nhập liệu'!$B$25,0) | E42: =B42-C42-D42 | F42: =MAX(0,'1. Nhập liệu'!$B$15-IF('1. Nhập liệu'!$B$19<=0,0,'1. Nhập liệu'!$B$15/'1. Nhập liệu'!$B$19)*(A42-1)) | G42: =MIN(IF('1. Nhập liệu'!$B$19<=0,0,'1. Nhập liệu'!$B$15/'1. Nhập liệu'!$B$19),F42) | H42: =ROUND((F42+(F42-G42))/2*(IF(A42=1,'1. Nhập liệu'!$B$17,'1. Nhập liệu'!$B$18)+$D$8),0) | I42: =G42+H42 | J42: =E42-I42 | K42: =IF(I42<=0,"—",ROUND(E42/I42,2))
A43: 2 | B43: =ROUND('1. Nhập liệu'!$B$22*(1+$D$6)*MAX(0,12-$D$7)*(1+$D$9)^(A43-1),0) | C43: =ROUND('1. Nhập liệu'!$B$24*12*(1+'1. Nhập liệu'!$B$29)^(A43-1),0) | D43: =ROUND(B43*'1. Nhập liệu'!$B$25,0) | E43: =B43-C43-D43 | F43: =MAX(0,'1. Nhập liệu'!$B$15-IF('1. Nhập liệu'!$B$19<=0,0,'1. Nhập liệu'!$B$15/'1. Nhập liệu'!$B$19)*(A43-1)) | G43: =MIN(IF('1. Nhập liệu'!$B$19<=0,0,'1. Nhập liệu'!$B$15/'1. Nhập liệu'!$B$19),F43) | H43: =ROUND((F43+(F43-G43))/2*(IF(A43=1,'1. Nhập liệu'!$B$17,'1. Nhập liệu'!$B$18)+$D$8),0) | I43: =G43+H43 | J43: =E43-I43 | K43: =IF(I43<=0,"—",ROUND(E43/I43,2))
A44: 3 | B44: =ROUND('1. Nhập liệu'!$B$22*(1+$D$6)*MAX(0,12-$D$7)*(1+$D$9)^(A44-1),0) | C44: =ROUND('1. Nhập liệu'!$B$24*12*(1+'1. Nhập liệu'!$B$29)^(A44-1),0) | D44: =ROUND(B44*'1. Nhập liệu'!$B$25,0) | E44: =B44-C44-D44 | F44: =MAX(0,'1. Nhập liệu'!$B$15-IF('1. Nhập liệu'!$B$19<=0,0,'1. Nhập liệu'!$B$15/'1. Nhập liệu'!$B$19)*(A44-1)) | G44: =MIN(IF('1. Nhập liệu'!$B$19<=0,0,'1. Nhập liệu'!$B$15/'1. Nhập liệu'!$B$19),F44) | H44: =ROUND((F44+(F44-G44))/2*(IF(A44=1,'1. Nhập liệu'!$B$17,'1. Nhập liệu'!$B$18)+$D$8),0) | I44: =G44+H44 | J44: =E44-I44 | K44: =IF(I44<=0,"—",ROUND(E44/I44,2))
A45: 4 | B45: =ROUND('1. Nhập liệu'!$B$22*(1+$D$6)*MAX(0,12-$D$7)*(1+$D$9)^(A45-1),0) | C45: =ROUND('1. Nhập liệu'!$B$24*12*(1+'1. Nhập liệu'!$B$29)^(A45-1),0) | D45: =ROUND(B45*'1. Nhập liệu'!$B$25,0) | E45: =B45-C45-D45 | F45: =MAX(0,'1. Nhập liệu'!$B$15-IF('1. Nhập liệu'!$B$19<=0,0,'1. Nhập liệu'!$B$15/'1. Nhập liệu'!$B$19)*(A45-1)) | G45: =MIN(IF('1. Nhập liệu'!$B$19<=0,0,'1. Nhập liệu'!$B$15/'1. Nhập liệu'!$B$19),F45) | H45: =ROUND((F45+(F45-G45))/2*(IF(A45=1,'1. Nhập liệu'!$B$17,'1. Nhập liệu'!$B$18)+$D$8),0) | I45: =G45+H45 | J45: =E45-I45 | K45: =IF(I45<=0,"—",ROUND(E45/I45,2))
...

Sheet 4. Đọc kết quả
A1: ĐỌC KẾT QUẢ BẰNG TIẾNG NGƯỜI
A2: Năm chỉ số quyết định nên mua hay không
A4: Chỉ số | B4: Nghĩa là gì | C4: Ngưỡng cảnh báo
A5: NOI | B5: Lãi ròng từ việc cho thuê trong một năm, sau khi trừ chi phí vận hành và thuế, nhưng CHƯA trừ tiền trả ngân hàng. Đây là sức khoẻ thật của toà nhà, không phụ thuộc anh/chị vay nhiều hay ít. | C5: NOI âm nghĩa là toà nhà tự nó đã lỗ. Không có cách vay nào cứu được.
A6: Cap Rate | B6: NOI chia cho số tiền bỏ ra. Trả lời câu: mỗi đồng vốn mang về bao nhiêu một năm. Dùng để so hai toà nhà khác giá với nhau. | C6: So Cap Rate với lãi gửi tiết kiệm. Thấp hơn tiết kiệm mà vẫn mua thì phải có lý do khác.
A7: DSCR | B7: NOI chia cho tổng tiền trả ngân hàng trong năm. Trả lời câu: tiền thuê có gánh nổi nợ không. | C7: Dưới 1,2 là ĐÈN ĐỎ — chỉ cần trống hai tháng là phải bù tiền túi. 1,2–1,5 là đèn vàng. Trên 1,5 là thở được.
A8: Dòng tiền ròng | B8: Số tiền thật sự còn lại trong túi sau khi đã trả ngân hàng. Đây là con số anh/chị tiêu được. | C8: Âm trong 12–18 tháng đầu là bình thường nếu có cải tạo. Âm quá 18 tháng là phải xem lại.
A9: Điểm hoà vốn | B9: Năm mà dòng tiền luỹ kế bù đủ phần vốn tự có đã bỏ ra. | C9: Toà nhà dòng tiền tốt thường thu hồi vốn tự có trong 7–10 năm, chưa tính phần tăng giá tài sản.
A11: BA CÂU HỎI TỰ ĐẶT TRƯỚC KHI ĐẶT CỌC
A12: 1. Nếu toà nhà để trống ba tháng liền, em có bù được không?
A13: 2. Nếu lãi suất thả nổi tăng thêm 2%, DSCR còn trên 1,2 không? (xem kịch bản Thận trọng)
A14: 3. Nếu năm năm nữa mới bán được, dòng tiền trong năm năm đó có đủ nuôi khoản vay không?
A16: Ba con số đẹp trên file này chưa phải là một quyết định đúng. Còn pháp lý, còn hiện trạng công trình, còn khách thuê. Nếu anh/chị muốn em cùng ngồi xuống đọc lại từng dòng cho chính toà nhà anh/chị đang nhắm — em luôn sẵn sàng, và không mất phí. Cộng Hưởng Cùng Viên Mãn · Nghĩ Thiện! · DAPANO GROUP
